Workbook

Sheet Dashboard
B1: Hiring Pipeline Dashboard
B2: MSE 100 hiring process model: tracks every candidate through the Software Developer, Graphic Designer and Commercial Team hiring paths.
B3: All candidate data is fictional. Numbers recalculate from the Candidates and Passing Scores tabs.
B4: TOTAL CANDIDATES | C4: IN PROCESS | F4: REJECTED | J4: REJECTION RATE | M4: ENTRIES TO REVIEW
B5: =COUNTA(Candidates!$A$2:$A$500) -> 29 | C5: =B5-F5-C22 -> 18 | F5: =COUNTIF(Candidates!$B$2:$B$500,"FAIL") -> 11 | J5: =IFERROR(F5/B5,0) -> 0.37931034 | M5: =COUNTIF(Candidates!F$2:F$500,">10")+COUNTIF(Candidates!F$2:F$500,"<0")+COUNTIF(Candidates!I$2:I$500,">10")+COUNTIF(Candidates!I$2:I$500,"<0")+COUNTIF(Candidates!L$2:L$500,">10")+COUNTIF(Candidates!L$2:L$500,"<0")+COUNTIF(Candidates!O$2:O$500,">10")+COUNTIF(Candidates!O$2:O$500,"<0")+COUNTIF(Candidates!R$2:R$500,">10")+COUNTIF(Candidates!R$2:R$500,"<0")+COUNTIF(Candidates!U$2:U$500,">10")+COUNTIF(Candidates!U$2:U$500,"<0")+COUNTIF(Candidates!X$2:X$500,">10")+COUNTIF(Candidates!X$2:X$500,"<0")+COUNTIF(Candidates!G$2:G$500,"<36526")+COUNTIF(Candidates!H$2:H$500,"<36526")+COUNTIF(Candidates!J$2:J$500,"<36526")+COUNTIF(Candidates!K$2:K$500,"<36526")+COUNTIF(Candidates!M$2:M$500,"<36526")+COUNTIF(Candidates!N$2:N$500,"<36526")+COUNTIF(Candidates!P$2:P$500,"<36526")+COUNTIF(Candidates!Q$2:Q$500,"<36526")+COUNTIF(Candidates!S$2:S$500,"<36526")+COUNTIF(Candidates!T$2:T$500,"<36526")+COUNTIF(Candidates!V$2:V$500,"<36526")+COUNTIF(Candidates!W$2:W$500,"<36526")+COUNTIF(Candidates!Y$2:Y$500,"<36526")+COUNTIF(Candidates!Z$2:Z$500,"<36526") -> 4
B6: Across all hiring paths | C6: Still moving through the pipeline | F6: Failed at least one stage | J6: Rejected divided by total | M6: Scores outside 0 to 10, or non-dates in date columns
B8: Results at each stage
B9: Stage | C9: Scored | D9: Passed | E9: Failed | F9: Pass rate | G9: Min score
B10: Resume Review | C10: =COUNT(Candidates!F$2:F$500) -> 29 | D10: =C10-E10 -> 22 | E10: =COUNTIF(Candidates!AI$2:AI$500,TRUE) -> 7 | F10: =IFERROR(D10/C10,0) -> 0.75862069 | G10: ='Passing Scores'!$B$1 -> 5
B11: Tech Assessment | C11: =COUNT(Candidates!I$2:I$500) -> 2 | D11: =C11-E11 -> 1 | E11: =COUNTIF(Candidates!AJ$2:AJ$500,TRUE) -> 1 | F11: =IFERROR(D11/C11,0) -> 0.5 | G11: ='Passing Scores'!$B$3 -> 7
B12: Initial Meeting | C12: =COUNT(Candidates!L$2:L$500) -> 3 | D12: =C12-E12 -> 2 | E12: =COUNTIF(Candidates!AK$2:AK$500,TRUE) -> 1 | F12: =IFERROR(D12/C12,0) -> 0.66666667 | G12: ='Passing Scores'!$B$4 -> 6
B13: Portfolio | C13: =COUNT(Candidates!O$2:O$500) -> 1 | D13: =C13-E13 -> 0 | E13: =COUNTIF(Candidates!AL$2:AL$500,TRUE) -> 1 | F13: =IFERROR(D13/C13,0) -> 0 | G13: ='Passing Scores'!$B$5 -> 7
B14: Personality Assessment | C14: =COUNT(Candidates!R$2:R$500) -> 7 | D14: =C14-E14 -> 2 | E14: =COUNTIF(Candidates!AM$2:AM$500,TRUE) -> 5 | F14: =IFERROR(D14/C14,0) -> 0.28571429 | G14: ='Passing Scores'!$B$6 -> 6
B15: Technical Interview | C15: =COUNT(Candidates!U$2:U$500) -> 1 | D15: =C15-E15 -> 0 | E15: =COUNTIF(Candidates!AN$2:AN$500,TRUE) -> 1 | F15: =IFERROR(D15/C15,0) -> 0 | G15: ='Passing Scores'!$B$7 -> 8
B16: Final Interview | C16: =COUNT(Candidates!X$2:X$500) -> 2 | D16: =C16-E16 -> 1 | E16: =COUNTIF(Candidates!AO$2:AO$500,TRUE) -> 1 | F16: =IFERROR(D16/C16,0) -> 0.5 | G16: ='Passing Scores'!$B$8 -> 8
B18: Pipeline status
B19: Status | C19: Candidates
B20: In process | C20: =C5 -> 18
B21: Rejected | C21: =F5 -> 11
B22: Offer signed | C22: =COUNT(Candidates!$Z$2:$Z$500) -> 0
B24: Hiring path
B25: Path | C25: Applicants | D25: Not rejected | E25: Rejected | F25: Rejection rate
B26: Software Developer | C26: =COUNTIF(Candidates!$D$2:$D$500,B26) -> 12 | D26: =C26-E26 -> 8 | E26: =COUNTIFS(Candidates!$D$2:$D$500,B26,Candidates!$B$2:$B$500,"FAIL") -> 4 | F26: =IFERROR(E26/C26,0) -> 0.33333333
B27: Graphic Designer | C27: =COUNTIF(Candidates!$D$2:$D$500,B27) -> 10 | D27: =C27-E27 -> 6 | E27: =COUNTIFS(Candidates!$D$2:$D$500,B27,Candidates!$B$2:$B$500,"FAIL") -> 4 | F27: =IFERROR(E27/C27,0) -> 0.4
B28: Commercial Team | C28: =COUNTIF(Candidates!$D$2:$D$500,B28) -> 7 | D28: =C28-E28 -> 4 | E28: =COUNTIFS(Candidates!$D$2:$D$500,B28,Candidates!$B$2:$B$500,"FAIL") -> 3 | F28: =IFERROR(E28/C28,0) -> 0.42857143
B30: Action queue: what each active candidate needs next
B31: Next step | C31: Candidates
B32: Review Resume | C32: =COUNTIF(Candidates!$B$2:$B$500,B32) -> 0
B33: Schedule Initial Meeting | C33: =COUNTIF(Candidates!$B$2:$B$500,B33) -> 7
B34: Conduct Initial Meeting | C34: =COUNTIF(Candidates!$B$2:$B$500,B34) -> 0
B35: Review Initial Meeting | C35: =COUNTIF(Candidates!$B$2:$B$500,B35) -> 0
B36: Send Technical Assessment | C36: =COUNTIF(Candidates!$B$2:$B$500,B36) -> 3
B37: Write Technical Assessment | C37: =COUNTIF(Candidates!$B$2:$B$500,B37) -> 1
B38: Review Technical Assessment | C38: =COUNTIF(Candidates!$B$2:$B$500,B38) -> 0
B39: Ask for Portfolio | C39: =COUNTIF(Candidates!$B$2:$B$500,B39) -> 4
B40: Send Portfolio | C40: =COUNTIF(Candidates!$B$2:$B$500,B40) -> 1
B41: Review Portfolio | C41: =COUNTIF(Candidates!$B$2:$B$500,B41) -> 0
B42: Send Personality Assessment | C42: =COUNTIF(Candidates!$B$2:$B$500,B42) -> 1
B43: Write Personality Assessment | C43: =COUNTIF(Candidates!$B$2:$B$500,B43) -> 0
... B53: Hired! | C53: =COUNTIF(Candidates!$B$2:$B$500,B53) -> 0
...

Sheet Candidates
A1: Name | B1: Next Step | C1: Position Applied | D1: Category | E1: Exceeds Expectations? | F1: Resume Score | G1: Send Tech Assessment | H1: Tech Assessment Done | I1: Tech Assessment Score | J1: Initial Meeting Scheduled | K1: Initial Meeting Conducted | L1: Initial Meeting Score | M1: Portfolio Requested | N1: Portfolio Received | O1: Portfolio Score | P1: Personality Assessment Sent | Q1: Personality Assessment Done | R1: Personality Assessment Score | S1: Tech Interview Scheduled | T1: Tech Interview Conducted | U1: Tech Interview Score | V1: Final Interview Scheduled | W1: Final Interview Conducted | X1: Final Interview Score | Y1: Offer Sent | Z1: Offer Signed | AA1: Base Process Code | AB1: Exceeding Code | AC1: Full Process Code | AD1: # Steps Complete | AE1: Process Column | AF1: Relevant Row | AG1: Active Status | AH1: Actual Status | AI1: Resume Fail | AJ1: Tech Assessment Fail | AK1: Initial Meeting Fail | AL1: Portfolio Fail | AM1: Personality Fail | AN1: Tech Interview Fail | AO1: Final Interview Fail | AP1: Overall Fail | AQ1: Min Resume Score | AR1: Exceeding Resume Score | AS1: Min Tech Assessment | AT1: Min Initial Meeting | AU1: Min Portfolio | AV1: Min Personality Assessment | AW1: Min Tech Interview | AX1: Min Final Interview
A2: William S Preston | B2: =AH2 -> FAIL | C2: Front-End Developer | D2: =VLOOKUP(C2, 'Job Info'!A:C, 2, FALSE) -> Software Developer | E2: =IF(F2 >= VLOOKUP("Resume Exceed", 'Passing Scores'!A:B, 2, FALSE), "yes", "no") -> no | F2: 7 | G2: 44816 | H2: 44816 | I2: 7 | J2: 44818 | K2: 44818 | L2: 5 | O2: 1 | R2: 1 | U2: 1 | V2: 1 | X2: 1 | AA2: =VLOOKUP(C2, 'Job Info'!A:C, 3, FALSE) -> SD | AB2: =UPPER(E2) -> NO | AC2: =AA2 & AB2 -> SDNO | AD2: =COUNT(F2:Z2) -> 12 | AE2: =HLOOKUP(AC2, 'Hiring Processes'!$A$3:$G$20, 2, FALSE) -> 4 | AF2: =4+AD2 -> 16 | AG2: =OFFSET('Hiring Processes'!$A$1,(Candidates!AF2),(Candidates!AE2)) -> Review Final Interview | AH2: =IF(AP2=TRUE, "FAIL", OFFSET('Hiring Processes'!$A$1,(AF2),(Candidates!AE2))) -> FAIL | AI2: =IF(AND(F2<'Passing Scores'!$B$1, COUNT(F2) = 1),TRUE,FALSE) -> FALSE | AJ2: =IF(AND(I2<'Passing Scores'!$B$3, COUNT(I2)=1),TRUE, FALSE) -> FALSE | AK2: =IF(AND(L2<'Passing Scores'!$B$4,COUNT(L2)=1),TRUE, FALSE) -> TRUE | AL2: =IF(AND(O2<'Passing Scores'!$B$5,COUNT(O2)=1),TRUE, FALSE) -> TRUE | AM2: =IF(AND(R2<'Passing Scores'!$B$6,COUNT(R2)=1),TRUE, FALSE) -> TRUE | AN2: =IF(AND(U2<'Passing Scores'!$B$7,COUNT(U2)=1),TRUE, FALSE) -> TRUE | AO2: =IF(AND(X2<'Passing Scores'!$B$8,COUNT(X2)=1),TRUE, FALSE) -> TRUE | AP2: =OR(AI2,AJ2,AK2,AL2,AM2,AN2,AO2) -> TRUE | AQ2: ='Passing Scores'!$B$1 -> 5 | AR2: ='Passing Scores'!$B$2 -> 8 | AS2: ='Passing Scores'!$B$3 -> 7 | AT2: ='Passing Scores'!$B$4 -> 6 | AU2: ='Passing Scores'!$B$5 -> 7 | AV2: ='Passing Scores'!$B$6 -> 6 | AW2: ='Passing Scores'!$B$7 -> 8 | AX2: ='Passing Scores'!$B$8 -> 8
A3: Ted Logan | B3: =AH3 -> Write Technical Assessment | C3: Back-End Developer | D3: =VLOOKUP(C3, 'Job Info'!A:C, 2, FALSE) -> Software Developer | E3: =IF(F3 >= VLOOKUP("Resume Exceed", 'Passing Scores'!A:B, 2, FALSE), "yes", "no") -> yes | F3: 9 | J3: 44818 | K3: 44818 | L3: 6 | X3: 22 | AA3: =VLOOKUP(C3, 'Job Info'!A:C, 3, FALSE) -> SD | AB3: =UPPER(E3) -> YES | AC3: =AA3 & AB3 -> SDYES | AD3: =COUNT(F3:Z3) -> 5 | AE3: =HLOOKUP(AC3, 'Hiring Processes'!$A$3:$G$20, 2, FALSE) -> 3 | AF3: =4+AD3 -> 9 | AG3: =OFFSET('Hiring Processes'!$A$1,(Candidates!AF3),(Candidates!AE3)) -> Write Technical Assessment | AH3: =IF(AP3=TRUE, "FAIL", OFFSET('Hiring Processes'!$A$1,(AF3),(Candidates!AE3))) -> Write Technical Assessment | AI3: =IF(AND(F3<'Passing Scores'!$B$1, COUNT(F3) = 1),TRUE,FALSE) -> FALSE | AJ3: =IF(AND(I3<'Passing Scores'!$B$3, COUNT(I3)=1),TRUE, FALSE) -> FALSE | AK3: =IF(AND(L3<'Passing Scores'!$B$4,COUNT(L3)=1),TRUE, FALSE) -> FALSE | AL3: =IF(AND(O3<'Passing Scores'!$B$5,COUNT(O3)=1),TRUE, FALSE) -> FALSE | AM3: =IF(AND(R3<'Passing Scores'!$B$6,COUNT(R3)=1),TRUE, FALSE) -> FALSE | AN3: =IF(AND(U3<'Passing Scores'!$B$7,COUNT(U3)=1),TRUE, FALSE) -> FALSE | AO3: =IF(AND(X3<'Passing Scores'!$B$8,COUNT(X3)=1),TRUE, FALSE) -> FALSE | AP3: =OR(AI3,AJ3,AK3,AL3,AM3,AN3,AO3) -> FALSE | AQ3: ='Passing Scores'!$B$1 -> 5 | AR3: ='Passing Scores'!$B$2 -> 8 | AS3: ='Passing Scores'!$B$3 -> 7 | AT3: ='Passing Scores'!$B$4 -> 6 | AU3: ='Passing Scores'!$B$5 -> 7 | AV3: ='Passing Scores'!$B$6 -> 6 | AW3: ='Passing Scores'!$B$7 -> 8 | AX3: ='Passing Scores'!$B$8 -> 8
A4: Wuce Brayne | B4: =AH4 -> FAIL | C4: Infrastructure Developer | D4: =VLOOKUP(C4, 'Job Info'!A:C, 2, FALSE) -> Software Developer | E4: =IF(F4 >= VLOOKUP("Resume Exceed", 'Passing Scores'!A:B, 2, FALSE), "yes", "no") -> no | F4: 4 | I4: 1 | AA4: =VLOOKUP(C4, 'Job Info'!A:C, 3, FALSE) -> SD | AB4: =UPPER(E4) -> NO | AC4: =AA4 & AB4 -> SDNO | AD4: =COUNT(F4:Z4) -> 2 | AE4: =HLOOKUP(AC4, 'Hiring Processes'!$A$3:$G$18, 2, FALSE) -> 4 | AF4: =4+AD4 -> 6 | AG4: =OFFSET('Hiring Processes'!$A$1,(Candidates!AF4),(Candidates!AE4)) -> Write Technical Assessment | AH4: =IF(AP4=TRUE, "FAIL", OFFSET('Hiring Processes'!$A$1,(AF4),(Candidates!AE4))) -> FAIL | AI4: =IF(AND(F4<'Passing Scores'!$B$1, COUNT(F4) = 1),TRUE,FALSE) -> TRUE | AJ4: =IF(AND(I4<'Passing Scores'!$B$3, COUNT(I4)=1),TRUE, FALSE) -> TRUE | AK4: =IF(AND(L4<'Passing Scores'!$B$4,COUNT(L4)=1),TRUE, FALSE) -> FALSE | AL4: =IF(AND(O4<'Passing Scores'!$B$5,COUNT(O4)=1),TRUE, FALSE) -> FALSE | AM4: =IF(AND(R4<'Passing Scores'!$B$6,COUNT(R4)=1),TRUE, FALSE) -> FALSE | AN4: =IF(AND(U4<'Passing Scores'!$B$7,COUNT(U4)=1),TRUE, FALSE) -> FALSE | AO4: =IF(AND(X4<'Passing Scores'!$B$8,COUNT(X4)=1),TRUE, FALSE) -> FALSE | AP4: =OR(AI4,AJ4,AK4,AL4,AM4,AN4,AO4) -> TRUE | AQ4: ='Passing Scores'!$B$1 -> 5 | AR4: ='Passing Scores'!$B$2 -> 8 | AS4: ='Passing Scores'!$B$3 -> 7 | AT4: ='Passing Scores'!$B$4 -> 6 | AU4: ='Passing Scores'!$B$5 -> 7 | AV4: ='Passing Scores'!$B$6 -> 6 | AW4: ='Passing Scores'!$B$7 -> 8 | AX4: ='Passing Scores'!$B$8 -> 8
A5: Kark Clent | B5: =AH5 -> Send Portfolio | C5: UI Designer | D5: =VLOOKUP(C5, 'Job Info'!A:C, 2, FALSE) -> Graphic Designer | E5: =IF(F5 >= VLOOKUP("Resume Exceed", 'Passing Scores'!A:B, 2, FALSE), "yes", "no") -> no | F5: 7 | R5: 7 | AA5: =VLOOKUP(C5, 'Job Info'!A:C, 3, FALSE) -> GD | AB5: =UPPER(E5) -> NO | AC5: =AA5 & AB5 -> GDNO | AD5: =COUNT(F5:Z5) -> 2 | AE5: =HLOOKUP(AC5, 'Hiring Processes'!$A$3:$G$18, 2, FALSE) -> 6 | AF5: =4+AD5 -> 6 | AG5: =OFFSET('Hiring Processes'!$A$1,(Candidates!AF5),(Candidates!AE5)) -> Send Portfolio | AH5: =IF(AP5=TRUE, "FAIL", OFFSET('Hiring Processes'!$A$1,(AF5),(Candidates!AE5))) -> Send Portfolio | AI5: =IF(AND(F5<'Passing Scores'!$B$1, COUNT(F5) = 1),TRUE,FALSE) -> FALSE | AJ5: =IF(AND(I5<'Passing Scores'!$B$3, COUNT(I5)=1),TRUE, FALSE) -> FALSE | AK5: =IF(AND(L5<'Passing Scores'!$B$4,COUNT(L5)=1),TRUE, FALSE) -> FALSE | AL5: =IF(AND(O5<'Passing Scores'!$B$5,COUNT(O5)=1),TRUE, FALSE) -> FALSE | AM5: =IF(AND(R5<'Passing Scores'!$B$6,COUNT(R5)=1),TRUE, FALSE) -> FALSE | AN5: =IF(AND(U5<'Passing Scores'!$B$7,COUNT(U5)=1),TRUE, FALSE) -> FALSE | AO5: =IF(AND(X5<'Passing Scores'!$B$8,COUNT(X5)=1),TRUE, FALSE) -> FALSE | AP5: =OR(AI5,AJ5,AK5,AL5,AM5,AN5,AO5) -> FALSE | AQ5: ='Passing Scores'!$B$1 -> 5 | AR5: ='Passing Scores'!$B$2 -> 8 | AS5: ='Passing Scores'!$B$3 -> 7 | AT5: ='Passing Scores'!$B$4 -> 6 | AU5: ='Passing Scores'!$B$5 -> 7 | AV5: ='Passing Scores'!$B$6 -> 6 | AW5: ='Passing Scores'!$B$7 -> 8 | AX5: ='Passing Scores'!$B$8 -> 8
A6: Stony Tark | B6: =AH6 -> FAIL | C6: UX Designer | D6: =VLOOKUP(C6, 'Job Info'!A:C, 2, FALSE) -> Graphic Designer | E6: =IF(F6 >= VLOOKUP("Resume Exceed", 'Passing Scores'!A:B, 2, FALSE), "yes", "no") -> no | F6: 7 | R6: 1 | AA6: =VLOOKUP(C6, 'Job Info'!A:C, 3, FALSE) -> GD | AB6: =UPPER(E6) -> NO | AC6: =AA6 & AB6 -> GDNO | AD6: =COUNT(F6:Z6) -> 2 | AE6: =HLOOKUP(AC6, 'Hiring Processes'!$A$3:$G$18, 2, FALSE) -> 6 | AF6: =4+AD6 -> 6 | AG6: =OFFSET('Hiring Processes'!$A$1,(Candidates!AF6),(Candidates!AE6)) -> Send Portfolio | AH6: =IF(AP6=TRUE, "FAIL", OFFSET('Hiring Processes'!$A$1,(AF6),(Candidates!AE6))) -> FAIL | AI6: =IF(AND(F6<'Passing Scores'!$B$1, COUNT(F6) = 1),TRUE,FALSE) -> FALSE | AJ6: =IF(AND(I6<'Passing Scores'!$B$3, COUNT(I6)=1),TRUE, FALSE) -> FALSE | AK6: =IF(AND(L6<'Passing Scores'!$B$4,COUNT(L6)=1),TRUE, FALSE) -> FALSE | AL6: =IF(AND(O6<'Passing Scores'!$B$5,COUNT(O6)=1),TRUE, FALSE) -> FALSE | AM6: =IF(AND(R6<'Passing Scores'!$B$6,COUNT(R6)=1),TRUE, FALSE) -> TRUE | AN6: =IF(AND(U6<'Passing Scores'!$B$7,COUNT(U6)=1),TRUE, FALSE) -> FALSE | AO6: =IF(AND(X6<'Passing Scores'!$B$8,COUNT(X6)=1),TRUE, FALSE) -> FALSE | AP6: =OR(AI6,AJ6,AK6,AL6,AM6,AN6,AO6) -> TRUE | AQ6: ='Passing Scores'!$B$1 -> 5 | AR6: ='Passing Scores'!$B$2 -> 8 | AS6: ='Passing Scores'!$B$3 -> 7 | AT6: ='Passing Scores'!$B$4 -> 6 | AU6: ='Passing Scores'!$B$5 -> 7 | AV6: ='Passing Scores'!$B$6 -> 6 | AW6: ='Passing Scores'!$B$7 -> 8 | AX6: ='Passing Scores'!$B$8 -> 8
A7: Reve Stogers | B7: =AH7 -> FAIL | C7: Multimedia Creator | D7: =VLOOKUP(C7, 'Job Info'!A:C, 2, FALSE) -> Graphic Designer | E7: =IF(F7 >= VLOOKUP("Resume Exceed", 'Passing Scores'!A:B, 2, FALSE), "yes", "no") -> no | F7: 3 | R7: 3 | AA7: =VLOOKUP(C7, 'Job Info'!A:C, 3, FALSE) -> GD | AB7: =UPPER(E7) -> NO | AC7: =AA7 & AB7 -> GDNO | AD7: =COUNT(F7:Z7) -> 2 | AE7: =HLOOKUP(AC7, 'Hiring Processes'!$A$3:$G$18, 2, FALSE) -> 6 | AF7: =4+AD7 -> 6 | AG7: =OFFSET('Hiring Processes'!$A$1,(Candidates!AF7),(Candidates!AE7)) -> Send Portfolio | AH7: =IF(AP7=TRUE, "FAIL", OFFSET('Hiring Processes'!$A$1,(AF7),(Candidates!AE7))) -> FAIL | AI7: =IF(AND(F7<'Passing Scores'!$B$1, COUNT(F7) = 1),TRUE,FALSE) -> TRUE | AJ7: =IF(AND(I7<'Passing Scores'!$B$3, COUNT(I7)=1),TRUE, FALSE) -> FALSE | AK7: =IF(AND(L7<'Passing Scores'!$B$4,COUNT(L7)=1),TRUE, FALSE) -> FALSE | AL7: =IF(AND(O7<'Passing Scores'!$B$5,COUNT(O7)=1),TRUE, FALSE) -> FALSE | AM7: =IF(AND(R7<'Passing Scores'!$B$6,COUNT(R7)=1),TRUE, FALSE) -> TRUE | AN7: =IF(AND(U7<'Passing Scores'!$B$7,COUNT(U7)=1),TRUE, FALSE) -> FALSE | AO7: =IF(AND(X7<'Passing Scores'!$B$8,COUNT(X7)=1),TRUE, FALSE) -> FALSE | AP7: =OR(AI7,AJ7,AK7,AL7,AM7,AN7,AO7) -> TRUE | AQ7: ='Passing Scores'!$B$1 -> 5 | AR7: ='Passing Scores'!$B$2 -> 8 | AS7: ='Passing Scores'!$B$3 -> 7 | AT7: ='Passing Scores'!$B$4 -> 6 | AU7: ='Passing Scores'!$B$5 -> 7 | AV7: ='Passing Scores'!$B$6 -> 6 | AW7: ='Passing Scores'!$B$7 -> 8 | AX7: ='Passing Scores'!$B$8 -> 8
A8: Xarles Chavier | B8: =AH8 -> Schedule Final Interview | C8: Business Operations Associate | D8: =VLOOKUP(C8, 'Job Info'!A:C, 2, FALSE) -> Commercial Team | E8: =IF(F8 >= VLOOKUP("Resume Exceed", 'Passing Scores'!A:B, 2, FALSE), "yes", "no") -> yes | F8: 9 | J8: 44818 | K8: 44818 | L8: 9 | P8: 44818 | Q8: 44818 | R8: 6 | AA8: =VLOOKUP(C8, 'Job Info'!A:C, 3, FALSE) -> CT | AB8: =UPPER(E8) -> YES | AC8: =AA8 & AB8 -> CTYES | AD8: =COUNT(F8:Z8) -> 7 | AE8: =HLOOKUP(AC8, 'Hiring Processes'!$A$3:$G$18, 2, FALSE) -> 1 | AF8: =4+AD8 -> 11 | AG8: =OFFSET('Hiring Processes'!$A$1,(Candidates!AF8),(Candidates!AE8)) -> Schedule Final Interview | AH8: =IF(AP8=TRUE, "FAIL", OFFSET('Hiring Processes'!$A$1,(AF8),(Candidates!AE8))) -> Schedule Final Interview | AI8: =IF(AND(F8<'Passing Scores'!$B$1, COUNT(F8) = 1),TRUE,FALSE) -> FALSE | AJ8: =IF(AND(I8<'Passing Scores'!$B$3, COUNT(I8)=1),TRUE, FALSE) -> FALSE | AK8: =IF(AND(L8<'Passing Scores'!$B$4,COUNT(L8)=1),TRUE, FALSE) -> FALSE | AL8: =IF(AND(O8<'Passing Scores'!$B$5,COUNT(O8)=1),TRUE, FALSE) -> FALSE | AM8: =IF(AND(R8<'Passing Scores'!$B$6,COUNT(R8)=1),TRUE, FALSE) -> FALSE | AN8: =IF(AND(U8<'Passing Scores'!$B$7,COUNT(U8)=1),TRUE, FALSE) -> FALSE | AO8: =IF(AND(X8<'Passing Scores'!$B$8,COUNT(X8)=1),TRUE, FALSE) -> FALSE | AP8: =OR(AI8,AJ8,AK8,AL8,AM8,AN8,AO8) -> FALSE | AQ8: ='Passing Scores'!$B$1 -> 5 | AR8: ='Passing Scores'!$B$2 -> 8 | AS8: ='Passing Scores'!$B$3 -> 7 | AT8: ='Passing Scores'!$B$4 -> 6 | AU8: ='Passing Scores'!$B$5 -> 7 | AV8: ='Passing Scores'!$B$6 -> 6 | AW8: ='Passing Scores'!$B$7 -> 8 | AX8: ='Passing Scores'!$B$8 -> 8
A9: Buce Branner | B9: =AH9 -> FAIL | C9: Commercial Lead | D9: =VLOOKUP(C9, 'Job Info'!A:C, 2, FALSE) -> Commercial Team | E9: =IF(F9 >= VLOOKUP("Resume Exceed", 'Passing Scores'!A:B, 2, FALSE), "yes", "no") -> no | F9: 6 | P9: 44818 | R9: 0 | AA9: =VLOOKUP(C9, 'Job Info'!A:C, 3, FALSE) -> CT | AB9: =UPPER(E9) -> NO | AC9: =AA9 & AB9 -> CTNO | AD9: =COUNT(F9:Z9) -> 3 | AE9: =HLOOKUP(AC9, 'Hiring Processes'!$A$3:$G$18, 2, FALSE) -> 2 | AF9: =4+AD9 -> 7 | AG9: =OFFSET('Hiring Processes'!$A$1,(Candidates!AF9),(Candidates!AE9)) -> Review Personality Assessment | AH9: =IF(AP9=TRUE, "FAIL", OFFSET('Hiring Processes'!$A$1,(AF9),(Candidates!AE9))) -> FAIL | AI9: =IF(AND(F9<'Passing Scores'!$B$1, COUNT(F9) = 1),TRUE,FALSE) -> FALSE | AJ9: =IF(AND(I9<'Passing Scores'!$B$3, COUNT(I9)=1),TRUE, FALSE) -> FALSE | AK9: =IF(AND(L9<'Passing Scores'!$B$4,COUNT(L9)=1),TRUE, FALSE) -> FALSE | AL9: =IF(AND(O9<'Passing Scores'!$B$5,COUNT(O9)=1),TRUE, FALSE) -> FALSE | AM9: =IF(AND(R9<'Passing Scores'!$B$6,COUNT(R9)=1),TRUE, FALSE) -> TRUE | AN9: =IF(AND(U9<'Passing Scores'!$B$7,COUNT(U9)=1),TRUE, FALSE) -> FALSE | AO9: =IF(AND(X9<'Passing Scores'!$B$8,COUNT(X9)=1),TRUE, FALSE) -> FALSE | AP9: =OR(AI9,AJ9,AK9,AL9,AM9,AN9,AO9) -> TRUE | AQ9: ='Passing Scores'!$B$1 -> 5 | AR9: ='Passing Scores'!$B$2 -> 8 | AS9: ='Passing Scores'!$B$3 -> 7 | AT9: ='Passing Scores'!$B$4 -> 6 | AU9: ='Passing Scores'!$B$5 -> 7 | AV9: ='Passing Scores'!$B$6 -> 6 | AW9: ='Passing Scores'!$B$7 -> 8 | AX9: ='Passing Scores'!$B$8 -> 8
A10: Peter Parker | B10: =AH10 -> FAIL | C10: Back-End Developer | D10: =VLOOKUP(C10, 'Job Info'!A:C, 2, FALSE) -> Software Developer | E10: =IF(F10 >= VLOOKUP("Resume Exceed", 'Passing Scores'!A:B, 2, FALSE), "yes", "no") -> no | F10: 7 | G10: 44818 | R10: 4 | V10: 22 | AA10: =VLOOKUP(C10, 'Job Info'!A:C, 3, FALSE) -> SD | AB10: =UPPER(E10) -> NO | AC10: =AA10 & AB10 -> SDNO | AD10: =COUNT(F10:Z10) -> 4 | AE10: =HLOOKUP(AC10, 'Hiring Processes'!$A$3:$G$18, 2, FALSE) -> 4 | AF10: =4+AD10 -> 8 | AG10: =OFFSET('Hiring Processes'!$A$1,(Candidates!AF10),(Candidates!AE10)) -> Schedule Initial Meeting | AH10: =IF(AP10=TRUE, "FAIL", OFFSET('Hiring Processes'!$A$1,(AF10),(Candidates!AE10))) -> FAIL | AI10: =IF(AND(F10<'Passing Scores'!$B$1, COUNT(F10) = 1),TRUE,FALSE) -> FALSE | AJ10: =IF(AND(I10<'Passing Scores'!$B$3, COUNT(I10)=1),TRUE, FALSE) -> FALSE | AK10: =IF(AND(L10<'Passing Scores'!$B$4,COUNT(L10)=1),TRUE, FALSE) -> FALSE | AL10: =IF(AND(O10<'Passing Scores'!$B$5,COUNT(O10)=1),TRUE, FALSE) -> FALSE | AM10: =IF(AND(R10<'Passing Scores'!$B$6,COUNT(R10)=1),TRUE, FALSE) -> TRUE | AN10: =IF(AND(U10<'Passing Scores'!$B$7,COUNT(U10)=1),TRUE, FALSE) -> FALSE | AO10: =IF(AND(X10<'Passing Scores'!$B$8,COUNT(X10)=1),TRUE, FALSE) -> FALSE | AP10: =OR(AI10,AJ10,AK10,AL10,AM10,AN10,AO10) -> TRUE | AQ10: ='Passing Scores'!$B$1 -> 5 | AR10: ='Passing Scores'!$B$2 -> 8 | AS10: ='Passing Scores'!$B$3 -> 7 | AT10: ='Passing Scores'!$B$4 -> 6 | AU10: ='Passing Scores'!$B$5 -> 7 | AV10: ='Passing Scores'!$B$6 -> 6 | AW10: ='Passing Scores'!$B$7 -> 8 | AX10: ='Passing Scores'!$B$8 -> 8
A11: Maunt Ay | B11: =AH11 -> Ask for Portfolio | C11: Multimedia Creator | D11: =VLOOKUP(C11, 'Job Info'!A:C, 2, FALSE) -> Graphic Designer | E11: =IF(F11 >= VLOOKUP("Resume Exceed", 'Passing Scores'!A:B, 2, FALSE), "yes", "no") -> no | F11: 7 | AA11: =VLOOKUP(C11, 'Job Info'!A:C, 3, FALSE) -> GD | AB11: =UPPER(E11) -> NO | AC11: =AA11 & AB11 -> GDNO | AD11: =COUNT(F11:Z11) -> 1 | AE11: =HLOOKUP(AC11, 'Hiring Processes'!$A$3:$G$18, 2, FALSE) -> 6 | AF11: =4+AD11 -> 5 | AG11: =OFFSET('Hiring Processes'!$A$1,(Candidates!AF11),(Candidates!AE11)) -> Ask for Portfolio | AH11: =IF(AP11=TRUE, "FAIL", OFFSET('Hiring Processes'!$A$1,(AF11),(Candidates!AE11))) -> Ask for Portfolio | AI11: =IF(AND(F11<'Passing Scores'!$B$1, COUNT(F11) = 1),TRUE,FALSE) -> FALSE | AJ11: =IF(AND(I11<'Passing Scores'!$B$3, COUNT(I11)=1),TRUE, FALSE) -> FALSE | AK11: =IF(AND(L11<'Passing Scores'!$B$4,COUNT(L11)=1),TRUE, FALSE) -> FALSE | AL11: =IF(AND(O11<'Passing Scores'!$B$5,COUNT(O11)=1),TRUE, FALSE) -> FALSE | AM11: =IF(AND(R11<'Passing Scores'!$B$6,COUNT(R11)=1),TRUE, FALSE) -> FALSE | AN11: =IF(AND(U11<'Passing Scores'!$B$7,COUNT(U11)=1),TRUE, FALSE) -> FALSE | AO11: =IF(AND(X11<'Passing Scores'!$B$8,COUNT(X11)=1),TRUE, FALSE) -> FALSE | AP11: =OR(AI11,AJ11,AK11,AL11,AM11,AN11,AO11) -> FALSE | AQ11: ='Passing Scores'!$B$1 -> 5 | AR11: ='Passing Scores'!$B$2 -> 8 | AS11: ='Passing Scores'!$B$3 -> 7 | AT11: ='Passing Scores'!$B$4 -> 6 | AU11: ='Passing Scores'!$B$5 -> 7 | AV11: ='Passing Scores'!$B$6 -> 6 | AW11: ='Passing Scores'!$B$7 -> 8 | AX11: ='Passing Scores'!$B$8 -> 8
A12: Ratasha Nomanov | B12: =AH12 -> FAIL | C12: Commercial Lead | D12: =VLOOKUP(C12, 'Job Info'!A:C, 2, FALSE) -> Commercial Team | E12: =IF(F12 >= VLOOKUP("Resume Exceed", 'Passing Scores'!A:B, 2, FALSE), "yes", "no") -> no | F12: 4 | V12: 1 | AA12: =VLOOKUP(C12, 'Job Info'!A:C, 3, FALSE) -> CT | AB12: =UPPER(E12) -> NO | AC12: =AA12 & AB12 -> CTNO | AD12: =COUNT(F12:Z12) -> 2 | AE12: =HLOOKUP(AC12, 'Hiring Processes'!$A$3:$G$18, 2, FALSE) -> 2 | AF12: =4+AD12 -> 6 | AG12: =OFFSET('Hiring Processes'!$A$1,(Candidates!AF12),(Candidates!AE12)) -> Write Personality Assessment | AH12: =IF(AP12=TRUE, "FAIL", OFFSET('Hiring Processes'!$A$1,(AF12),(Candidates!AE12))) -> FAIL | AI12: =IF(AND(F12<'Passing Scores'!$B$1, COUNT(F12) = 1),TRUE,FALSE) -> TRUE | AJ12: =IF(AND(I12<'Passing Scores'!$B$3, COUNT(I12)=1),TRUE, FALSE) -> FALSE | AK12: =IF(AND(L12<'Passing Scores'!$B$4,COUNT(L12)=1),TRUE, FALSE) -> FALSE | AL12: =IF(AND(O12<'Passing Scores'!$B$5,COUNT(O12)=1),TRUE, FALSE) -> FALSE | AM12: =IF(AND(R12<'Passing Scores'!$B$6,COUNT(R12)=1),TRUE, FALSE) -> FALSE | AN12: =IF(AND(U12<'Passing Scores'!$B$7,COUNT(U12)=1),TRUE, FALSE) -> FALSE | AO12: =IF(AND(X12<'Passing Scores'!$B$8,COUNT(X12)=1),TRUE, FALSE) -> FALSE | AP12: =OR(AI12,AJ12,AK12,AL12,AM12,AN12,AO12) -> TRUE | AQ12: ='Passing Scores'!$B$1 -> 5 | AR12: ='Passing Scores'!$B$2 -> 8 | AS12: ='Passing Scores'!$B$3 -> 7 | AT12: ='Passing Scores'!$B$4 -> 6 | AU12: ='Passing Scores'!$B$5 -> 7 | AV12: ='Passing Scores'!$B$6 -> 6 | AW12: ='Passing Scores'!$B$7 -> 8 | AX12: ='Passing Scores'!$B$8 -> 8
A13: Arry Ballen | B13: =AH13 -> FAIL | C13: UX Designer | D13: =VLOOKUP(C13, 'Job Info'!A:C, 2, FALSE) -> Graphic Designer | E13: =IF(F13 >= VLOOKUP("Resume Exceed", 'Passing Scores'!A:B, 2, FALSE), "yes", "no") -> no | F13: 1 | AA13: =VLOOKUP(C13, 'Job Info'!A:C, 3, FALSE) -> GD | AB13: =UPPER(E13) -> NO | AC13: =AA13 & AB13 -> GDNO | AD13: =COUNT(F13:Z13) -> 1 | AE13: =HLOOKUP(AC13, 'Hiring Processes'!$A$3:$G$18, 2, FALSE) -> 6 | AF13: =4+AD13 -> 5 | AG13: =OFFSET('Hiring Processes'!$A$1,(Candidates!AF13),(Candidates!AE13)) -> Ask for Portfolio | AH13: =IF(AP13=TRUE, "FAIL", OFFSET('Hiring Processes'!$A$1,(AF13),(Candidates!AE13))) -> FAIL | AI13: =IF(AND(F13<'Passing Scores'!$B$1, COUNT(F13) = 1),TRUE,FALSE) -> TRUE | AJ13: =IF(AND(I13<'Passing Scores'!$B$3, COUNT(I13)=1),TRUE, FALSE) -> FALSE | AK13: =IF(AND(L13<'Passing Scores'!$B$4,COUNT(L13)=1),TRUE, FALSE) -> FALSE | AL13: =IF(AND(O13<'Passing Scores'!$B$5,COUNT(O13)=1),TRUE, FALSE) -> FALSE | AM13: =IF(AND(R13<'Passing Scores'!$B$6,COUNT(R13)=1),TRUE, FALSE) -> FALSE | AN13: =IF(AND(U13<'Passing Scores'!$B$7,COUNT(U13)=1),TRUE, FALSE) -> FALSE | AO13: =IF(AND(X13<'Passing Scores'!$B$8,COUNT(X13)=1),TRUE, FALSE) -> FALSE | AP13: =OR(AI13,AJ13,AK13,AL13,AM13,AN13,AO13) -> TRUE | AQ13: ='Passing Scores'!$B$1 -> 5 | AR13: ='Passing Scores'!$B$2 -> 8 | AS13: ='Passing Scores'!$B$3 -> 7 | AT13: ='Passing Scores'!$B$4 -> 6 | AU13: ='Passing Scores'!$B$5 -> 7 | AV13: ='Passing Scores'!$B$6 -> 6 | AW13: ='Passing Scores'!$B$7 -> 8 | AX13: ='Passing Scores'!$B$8 -> 8
A14: Billie Jean | B14: =AH14 -> FAIL | C14: UI Designer | D14: =VLOOKUP(C14, 'Job Info'!A:C, 2, FALSE) -> Graphic Designer | E14: =IF(F14 >= VLOOKUP("Resume Exceed", 'Passing Scores'!A:B, 2, FALSE), "yes", "no") -> no | F14: 2 | AA14: =VLOOKUP(C14, 'Job Info'!A:C, 3, FALSE) -> GD | AB14: =UPPER(E14) -> NO | AC14: =AA14 & AB14 -> GDNO | AD14: =COUNT(F14:Z14) -> 1 | AE14: =HLOOKUP(AC14, 'Hiring Processes'!$A$3:$G$18, 2, FALSE) -> 6 | AF14: =4+AD14 -> 5 | AG14: =OFFSET('Hiring Processes'!$A$1,(Candidates!AF14),(Candidates!AE14)) -> Ask for Portfolio | AH14: =IF(AP14=TRUE, "FAIL", OFFSET('Hiring Processes'!$A$1,(AF14),(Candidates!AE14))) -> FAIL | AI14: =IF(AND(F14<'Passing Scores'!$B$1, COUNT(F14) = 1),TRUE,FALSE) -> TRUE | AJ14: =IF(AND(I14<'Passing Scores'!$B$3, COUNT(I14)=1),TRUE, FALSE) -> FALSE | AK14: =IF(AND(L14<'Passing Scores'!$B$4,COUNT(L14)=1),TRUE, FALSE) -> FALSE | AL14: =IF(AND(O14<'Passing Scores'!$B$5,COUNT(O14)=1),TRUE, FALSE) -> FALSE | AM14: =IF(AND(R14<'Passing Scores'!$B$6,COUNT(R14)=1),TRUE, FALSE) -> FALSE | AN14: =IF(AND(U14<'Passing Scores'!$B$7,COUNT(U14)=1),TRUE, FALSE) -> FALSE | AO14: =IF(AND(X14<'Passing Scores'!$B$8,COUNT(X14)=1),TRUE, FALSE) -> FALSE | AP14: =OR(AI14,AJ14,AK14,AL14,AM14,AN14,AO14) -> TRUE | AQ14: ='Passing Scores'!$B$1 -> 5 | AR14: ='Passing Scores'!$B$2 -> 8 | AS14: ='Passing Scores'!$B$3 -> 7 | AT14: ='Passing Scores'!$B$4 -> 6 | AU14: ='Passing Scores'!$B$5 -> 7 | AV14: ='Passing Scores'!$B$6 -> 6 | AW14: ='Passing Scores'!$B$7 -> 8 | AX14: ='Passing Scores'!$B$8 -> 8
A15: Cotton Eye Joe | B15: =AH15 -> FAIL | C15: Front-End Developer | D15: =VLOOKUP(C15, 'Job Info'!A:C, 2, FALSE) -> Software Developer | E15: =IF(F15 >= VLOOKUP("Resume Exceed", 'Passing Scores'!A:B, 2, FALSE), "yes", "no") -> no | F15: 3 | AA15: =VLOOKUP(C15, 'Job Info'!A:C, 3, FALSE) -> SD | AB15: =UPPER(E15) -> NO | AC15: =AA15 & AB15 -> SDNO | AD15: =COUNT(F15:Z15) -> 1 | AE15: =HLOOKUP(AC15, 'Hiring Processes'!$A$3:$G$18, 2, FALSE) -> 4 | AF15: =4+AD15 -> 5 | AG15: =OFFSET('Hiring Processes'!$A$1,(Candidates!AF15),(Candidates!AE15)) -> Send Technical Assessment | AH15: =IF(AP15=TRUE, "FAIL", OFFSET('Hiring Processes'!$A$1,(AF15),(Candidates!AE15))) -> FAIL | AI15: =IF(AND(F15<'Passing Scores'!$B$1, COUNT(F15) = 1),TRUE,FALSE) -> TRUE | AJ15: =IF(AND(I15<'Passing Scores'!$B$3, COUNT(I15)=1),TRUE, FALSE) -> FALSE | AK15: =IF(AND(L15<'Passing Scores'!$B$4,COUNT(L15)=1),TRUE, FALSE) -> FALSE | AL15: =IF(AND(O15<'Passing Scores'!$B$5,COUNT(O15)=1),TRUE, FALSE) -> FALSE | AM15: =IF(AND(R15<'Passing Scores'!$B$6,COUNT(R15)=1),TRUE, FALSE) -> FALSE | AN15: =IF(AND(U15<'Passing Scores'!$B$7,COUNT(U15)=1),TRUE, FALSE) -> FALSE | AO15: =IF(AND(X15<'Passing Scores'!$B$8,COUNT(X15)=1),TRUE, FALSE) -> FALSE | AP15: =OR(AI15,AJ15,AK15,AL15,AM15,AN15,AO15) -> TRUE | AQ15: ='Passing Scores'!$B$1 -> 5 | AR15: ='Passing Scores'!$B$2 -> 8 | AS15: ='Passing Scores'!$B$3 -> 7 | AT15: ='Passing Scores'!$B$4 -> 6 | AU15: ='Passing Scores'!$B$5 -> 7 | AV15: ='Passing Scores'!$B$6 -> 6 | AW15: ='Passing Scores'!$B$7 -> 8 | AX15: ='Passing Scores'!$B$8 -> 8
A16: Rain Lu | B16: =AH16 -> FAIL | C16: Business Operations Associate | D16: =VLOOKUP(C16, 'Job Info'!A:C, 2, FALSE) -> Commercial Team | E16: =IF(F16 >= VLOOKUP("Resume Exceed", 'Passing Scores'!A:B, 2, FALSE), "yes", "no") -> no | F16: 4 | AA16: =VLOOKUP(C16, 'Job Info'!A:C, 3, FALSE) -> CT | AB16: =UPPER(E16) -> NO | AC16: =AA16 & AB16 -> CTNO | AD16: =COUNT(F16:Z16) -> 1 | AE16: =HLOOKUP(AC16, 'Hiring Processes'!$A$3:$G$18, 2, FALSE) -> 2 | AF16: =4+AD16 -> 5 | AG16: =OFFSET('Hiring Processes'!$A$1,(Candidates!AF16),(Candidates!AE16)) -> Send Personality Assessment | AH16: =IF(AP16=TRUE, "FAIL", OFFSET('Hiring Processes'!$A$1,(AF16),(Candidates!AE16))) -> FAIL | AI16: =IF(AND(F16<'Passing Scores'!$B$1, COUNT(F16) = 1),TRUE,FALSE) -> TRUE | AJ16: =IF(AND(I16<'Passing Scores'!$B$3, COUNT(I16)=1),TRUE, FALSE) -> FALSE | AK16: =IF(AND(L16<'Passing Scores'!$B$4,COUNT(L16)=1),TRUE, FALSE) -> FALSE | AL16: =IF(AND(O16<'Passing Scores'!$B$5,COUNT(O16)=1),TRUE, FALSE) -> FALSE | AM16: =IF(AND(R16<'Passing Scores'!$B$6,COUNT(R16)=1),TRUE, FALSE) -> FALSE | AN16: =IF(AND(U16<'Passing Scores'!$B$7,COUNT(U16)=1),TRUE, FALSE) -> FALSE | AO16: =IF(AND(X16<'Passing Scores'!$B$8,COUNT(X16)=1),TRUE, FALSE) -> FALSE | AP16: =OR(AI16,AJ16,AK16,AL16,AM16,AN16,AO16) -> TRUE | AQ16: ='Passing Scores'!$B$1 -> 5 | AR16: ='Passing Scores'!$B$2 -> 8 | AS16: ='Passing Scores'!$B$3 -> 7 | AT16: ='Passing Scores'!$B$4 -> 6 | AU16: ='Passing Scores'!$B$5 -> 7 | AV16: ='Passing Scores'!$B$6 -> 6 | AW16: ='Passing Scores'!$B$7 -> 8 | AX16: ='Passing Scores'!$B$8 -> 8
A17: Om Patel | B17: =AH17 -> Send Technical Assessment | C17: Infrastructure Developer | D17: =VLOOKUP(C17, 'Job Info'!A:C, 2, FALSE) -> Software Developer | E17: =IF(F17 >= VLOOKUP("Resume Exceed", 'Passing Scores'!A:B, 2, FALSE), "yes", "no") -> no | F17: 5 | AA17: =VLOOKUP(C17, 'Job Info'!A:C, 3, FALSE) -> SD | AB17: =UPPER(E17) -> NO | AC17: =AA17 & AB17 -> SDNO | AD17: =COUNT(F17:Z17) -> 1 | AE17: =HLOOKUP(AC17, 'Hiring Processes'!$A$3:$G$18, 2, FALSE) -> 4 | AF17: =4+AD17 -> 5 | AG17: =OFFSET('Hiring Processes'!$A$1,(Candidates!AF17),(Candidates!AE17)) -> Send Technical Assessment | AH17: =IF(AP17=TRUE, "FAIL", OFFSET('Hiring Processes'!$A$1,(AF17),(Candidates!AE17))) -> Send Technical Assessment | AI17: =IF(AND(F17<'Passing Scores'!$B$1, COUNT(F17) = 1),TRUE,FALSE) -> FALSE | AJ17: =IF(AND(I17<'Passing Scores'!$B$3, COUNT(I17)=1),TRUE, FALSE) -> FALSE | AK17: =IF(AND(L17<'Passing Scores'!$B$4,COUNT(L17)=1),TRUE, FALSE) -> FALSE | AL17: =IF(AND(O17<'Passing Scores'!$B$5,COUNT(O17)=1),TRUE, FALSE) -> FALSE | AM17: =IF(AND(R17<'Passing Scores'!$B$6,COUNT(R17)=1),TRUE, FALSE) -> FALSE | AN17: =IF(AND(U17<'Passing Scores'!$B$7,COUNT(U17)=1),TRUE, FALSE) -> FALSE | AO17: =IF(AND(X17<'Passing Scores'!$B$8,COUNT(X17)=1),TRUE, FALSE) -> FALSE | AP17: =OR(AI17,AJ17,AK17,AL17,AM17,AN17,AO17) -> FALSE | AQ17: ='Passing Scores'!$B$1 -> 5 | AR17: ='Passing Scores'!$B$2 -> 8 | AS17: ='Passing Scores'!$B$3 -> 7 | AT17: ='Passing Scores'!$B$4 -> 6 | AU17: ='Passing Scores'!$B$5 -> 7 | AV17: ='Passing Scores'!$B$6 -> 6 | AW17: ='Passing Scores'!$B$7 -> 8 | AX17: ='Passing Scores'!$B$8 -> 8
A18: David Wheatle | B18: =AH18 -> Ask for Portfolio | C18: UX Designer | D18: =VLOOKUP(C18, 'Job Info'!A:C, 2, FALSE) -> Graphic Designer | E18: =IF(F18 >= VLOOKUP("Resume Exceed", 'Passing Scores'!A:B, 2, FALSE), "yes", "no") -> no | F18: 6 | AA18: =VLOOKUP(C18, 'Job Info'!A:C, 3, FALSE) -> GD | AB18: =UPPER(E18) -> NO | AC18: =AA18 & AB18 -> GDNO | AD18: =COUNT(F18:Z18) -> 1 | AE18: =HLOOKUP(AC18, 'Hiring Processes'!$A$3:$G$18, 2, FALSE) -> 6 | AF18: =4+AD18 -> 5 | AG18: =OFFSET('Hiring Processes'!$A$1,(Candidates!AF18),(Candidates!AE18)) -> Ask for Portfolio | AH18: =IF(AP18=TRUE, "FAIL", OFFSET('Hiring Processes'!$A$1,(AF18),(Candidates!AE18))) -> Ask for Portfolio | AI18: =IF(AND(F18<'Passing Scores'!$B$1, COUNT(F18) = 1),TRUE,FALSE) -> FALSE | AJ18: =IF(AND(I18<'Passing Scores'!$B$3, COUNT(I18)=1),TRUE, FALSE) -> FALSE | AK18: =IF(AND(L18<'Passing Scores'!$B$4,COUNT(L18)=1),TRUE, FALSE) -> FALSE | AL18: =IF(AND(O18<'Passing Scores'!$B$5,COUNT(O18)=1),TRUE, FALSE) -> FALSE | AM18: =IF(AND(R18<'Passing Scores'!$B$6,COUNT(R18)=1),TRUE, FALSE) -> FALSE | AN18: =IF(AND(U18<'Passing Scores'!$B$7,COUNT(U18)=1),TRUE, FALSE) -> FALSE | AO18: =IF(AND(X18<'Passing Scores'!$B$8,COUNT(X18)=1),TRUE, FALSE) -> FALSE | AP18: =OR(AI18,AJ18,AK18,AL18,AM18,AN18,AO18) -> FALSE | AQ18: ='Passing Scores'!$B$1 -> 5 | AR18: ='Passing Scores'!$B$2 -> 8 | AS18: ='Passing Scores'!$B$3 -> 7 | AT18: ='Passing Scores'!$B$4 -> 6 | AU18: ='Passing Scores'!$B$5 -> 7 | AV18: ='Passing Scores'!$B$6 -> 6 | AW18: ='Passing Scores'!$B$7 -> 8 | AX18: ='Passing Scores'!$B$8 -> 8
A19: Julian Gaidola | B19: =AH19 -> Send Technical Assessment | C19: Back-End Developer | D19: =VLOOKUP(C19, 'Job Info'!A:C, 2, FALSE) -> Software Developer | E19: =IF(F19 >= VLOOKUP("Resume Exceed", 'Passing Scores'!A:B, 2, FALSE), "yes", "no") -> no | F19: 7 | AA19: =VLOOKUP(C19, 'Job Info'!A:C, 3, FALSE) -> SD | AB19: =UPPER(E19) -> NO | AC19: =AA19 & AB19 -> SDNO | AD19: =COUNT(F19:Z19) -> 1 | AE19: =HLOOKUP(AC19, 'Hiring Processes'!$A$3:$G$18, 2, FALSE) -> 4 | AF19: =4+AD19 -> 5 | AG19: =OFFSET('Hiring Processes'!$A$1,(Candidates!AF19),(Candidates!AE19)) -> Send Technical Assessment | AH19: =IF(AP19=TRUE, "FAIL", OFFSET('Hiring Processes'!$A$1,(AF19),(Candidates!AE19))) -> Send Technical Assessment | AI19: =IF(AND(F19<'Passing Scores'!$B$1, COUNT(F19) = 1),TRUE,FALSE) -> FALSE | AJ19: =IF(AND(I19<'Passing Scores'!$B$3, COUNT(I19)=1),TRUE, FALSE) -> FALSE | AK19: =IF(AND(L19<'Passing Scores'!$B$4,COUNT(L19)=1),TRUE, FALSE) -> FALSE | AL19: =IF(AND(O19<'Passing Scores'!$B$5,COUNT(O19)=1),TRUE, FALSE) -> FALSE | AM19: =IF(AND(R19<'Passing Scores'!$B$6,COUNT(R19)=1),TRUE, FALSE) -> FALSE | AN19: =IF(AND(U19<'Passing Scores'!$B$7,COUNT(U19)=1),TRUE, FALSE) -> FALSE | AO19: =IF(AND(X19<'Passing Scores'!$B$8,COUNT(X19)=1),TRUE, FALSE) -> FALSE | AP19: =OR(AI19,AJ19,AK19,AL19,AM19,AN19,AO19) -> FALSE | AQ19: ='Passing Scores'!$B$1 -> 5 | AR19: ='Passing Scores'!$B$2 -> 8 | AS19: ='Passing Scores'!$B$3 -> 7 | AT19: ='Passing Scores'!$B$4 -> 6 | AU19: ='Passing Scores'!$B$5 -> 7 | AV19: ='Passing Scores'!$B$6 -> 6 | AW19: ='Passing Scores'!$B$7 -> 8 | AX19: ='Passing Scores'!$B$8 -> 8
A20: Sophia Scott | B20: =AH20 -> Schedule Initial Meeting | C20: Front-End Developer | D20: =VLOOKUP(C20, 'Job Info'!A:C, 2, FALSE) -> Software Developer | E20: =IF(F20 >= VLOOKUP("Resume Exceed", 'Passing Scores'!A:B, 2, FALSE), "yes", "no") -> yes | F20: 8 | AA20: =VLOOKUP(C20, 'Job Info'!A:C, 3, FALSE) -> SD | AB20: =UPPER(E20) -> YES | AC20: =AA20 & AB20 -> SDYES | AD20: =COUNT(F20:Z20) -> 1 | AE20: =HLOOKUP(AC20, 'Hiring Processes'!$A$3:$G$18, 2, FALSE) -> 3 | AF20: =4+AD20 -> 5 | AG20: =OFFSET('Hiring Processes'!$A$1,(Candidates!AF20),(Candidates!AE20)) -> Schedule Initial Meeting | AH20: =IF(AP20=TRUE, "FAIL", OFFSET('Hiring Processes'!$A$1,(AF20),(Candidates!AE20))) -> Schedule Initial Meeting | AI20: =IF(AND(F20<'Passing Scores'!$B$1, COUNT(F20) = 1),TRUE,FALSE) -> FALSE | AJ20: =IF(AND(I20<'Passing Scores'!$B$3, COUNT(I20)=1),TRUE, FALSE) -> FALSE | AK20: =IF(AND(L20<'Passing Scores'!$B$4,COUNT(L20)=1),TRUE, FALSE) -> FALSE | AL20: =IF(AND(O20<'Passing Scores'!$B$5,COUNT(O20)=1),TRUE, FALSE) -> FALSE | AM20: =IF(AND(R20<'Passing Scores'!$B$6,COUNT(R20)=1),TRUE, FALSE) -> FALSE | AN20: =IF(AND(U20<'Passing Scores'!$B$7,COUNT(U20)=1),TRUE, FALSE) -> FALSE | AO20: =IF(AND(X20<'Passing Scores'!$B$8,COUNT(X20)=1),TRUE, FALSE) -> FALSE | AP20: =OR(AI20,AJ20,AK20,AL20,AM20,AN20,AO20) -> FALSE | AQ20: ='Passing Scores'!$B$1 -> 5 | AR20: ='Passing Scores'!$B$2 -> 8 | AS20: ='Passing Scores'!$B$3 -> 7 | AT20: ='Passing Scores'!$B$4 -> 6 | AU20: ='Passing Scores'!$B$5 -> 7 | AV20: ='Passing Scores'!$B$6 -> 6 | AW20: ='Passing Scores'!$B$7 -> 8 | AX20: ='Passing Scores'!$B$8 -> 8
A21: Sneverous Sape | B21: =AH21 -> Schedule Initial Meeting | C21: UI Designer | D21: =VLOOKUP(C21, 'Job Info'!A:C, 2, FALSE) -> Graphic Designer | E21: =IF(F21 >= VLOOKUP("Resume Exceed", 'Passing Scores'!A:B, 2, FALSE), "yes", "no") -> yes | F21: 9 | AA21: =VLOOKUP(C21, 'Job Info'!A:C, 3, FALSE) -> GD | AB21: =UPPER(E21) -> YES | AC21: =AA21 & AB21 -> GDYES | AD21: =COUNT(F21:Z21) -> 1 | AE21: =HLOOKUP(AC21, 'Hiring Processes'!$A$3:$G$18, 2, FALSE) -> 5 | AF21: =4+AD21 -> 5 | AG21: =OFFSET('Hiring Processes'!$A$1,(Candidates!AF21),(Candidates!AE21)) -> Schedule Initial Meeting | AH21: =IF(AP21=TRUE, "FAIL", OFFSET('Hiring Processes'!$A$1,(AF21),(Candidates!AE21))) -> Schedule Initial Meeting | AI21: =IF(AND(F21<'Passing Scores'!$B$1, COUNT(F21) = 1),TRUE,FALSE) -> FALSE | AJ21: =IF(AND(I21<'Passing Scores'!$B$3, COUNT(I21)=1),TRUE, FALSE) -> FALSE | AK21: =IF(AND(L21<'Passing Scores'!$B$4,COUNT(L21)=1),TRUE, FALSE) -> FALSE | AL21: =IF(AND(O21<'Passing Scores'!$B$5,COUNT(O21)=1),TRUE, FALSE) -> FALSE | AM21: =IF(AND(R21<'Passing Scores'!$B$6,COUNT(R21)=1),TRUE, FALSE) -> FALSE | AN21: =IF(AND(U21<'Passing Scores'!$B$7,COUNT(U21)=1),TRUE, FALSE) -> FALSE | AO21: =IF(AND(X21<'Passing Scores'!$B$8,COUNT(X21)=1),TRUE, FALSE) -> FALSE | AP21: =OR(AI21,AJ21,AK21,AL21,AM21,AN21,AO21) -> FALSE | AQ21: ='Passing Scores'!$B$1 -> 5 | AR21: ='Passing Scores'!$B$2 -> 8 | AS21: ='Passing Scores'!$B$3 -> 7 | AT21: ='Passing Scores'!$B$4 -> 6 | AU21: ='Passing Scores'!$B$5 -> 7 | AV21: ='Passing Scores'!$B$6 -> 6 | AW21: ='Passing Scores'!$B$7 -> 8 | AX21: ='Passing Scores'!$B$8 -> 8
A22: Leville Nongbottom | B22: =AH22 -> Schedule Initial Meeting | C22: Business Operations Associate | D22: =VLOOKUP(C22, 'Job Info'!A:C, 2, FALSE) -> Commercial Team | E22: =IF(F22 >= VLOOKUP("Resume Exceed", 'Passing Scores'!A:B, 2, FALSE), "yes", "no") -> yes | F22: 10 | AA22: =VLOOKUP(C22, 'Job Info'!A:C, 3, FALSE) -> CT | AB22: =UPPER(E22) -> YES | AC22: =AA22 & AB22 -> CTYES | AD22: =COUNT(F22:Z22) -> 1 | AE22: =HLOOKUP(AC22, 'Hiring Processes'!$A$3:$G$18, 2, FALSE) -> 1 | AF22: =4+AD22 -> 5 | AG22: =OFFSET('Hiring Processes'!$A$1,(Candidates!AF22),(Candidates!AE22)) -> Schedule Initial Meeting | AH22: =IF(AP22=TRUE, "FAIL", OFFSET('Hiring Processes'!$A$1,(AF22),(Candidates!AE22))) -> Schedule Initial Meeting | AI22: =IF(AND(F22<'Passing Scores'!$B$1, COUNT(F22) = 1),TRUE,FALSE) -> FALSE | AJ22: =IF(AND(I22<'Passing Scores'!$B$3, COUNT(I22)=1),TRUE, FALSE) -> FALSE | AK22: =IF(AND(L22<'Passing Scores'!$B$4,COUNT(L22)=1),TRUE, FALSE) -> FALSE | AL22: =IF(AND(O22<'Passing Scores'!$B$5,COUNT(O22)=1),TRUE, FALSE) -> FALSE | AM22: =IF(AND(R22<'Passing Scores'!$B$6,COUNT(R22)=1),TRUE, FALSE) -> FALSE | AN22: =IF(AND(U22<'Passing Scores'!$B$7,COUNT(U22)=1),TRUE, FALSE) -> FALSE | AO22: =IF(AND(X22<'Passing Scores'!$B$8,COUNT(X22)=1),TRUE, FALSE) -> FALSE | AP22: =OR(AI22,AJ22,AK22,AL22,AM22,AN22,AO22) -> FALSE | AQ22: ='Passing Scores'!$B$1 -> 5 | AR22: ='Passing Scores'!$B$2 -> 8 | AS22: ='Passing Scores'!$B$3 -> 7 | AT22: ='Passing Scores'!$B$4 -> 6 | AU22: ='Passing Scores'!$B$5 -> 7 | AV22: ='Passing Scores'!$B$6 -> 6 | AW22: ='Passing Scores'!$B$7 -> 8 | AX22: ='Passing Scores'!$B$8 -> 8
A23: Parry Hotter | B23: =AH23 -> Send Technical Assessment | C23: Infrastructure Developer | D23: =VLOOKUP(C23, 'Job Info'!A:C, 2, FALSE) -> Software Developer | E23: =IF(F23 >= VLOOKUP("Resume Exceed", 'Passing Scores'!A:B, 2, FALSE), "yes", "no") -> no | F23: 7 | AA23: =VLOOKUP(C23, 'Job Info'!A:C, 3, FALSE) -> SD | AB23: =UPPER(E23) -> NO | AC23: =AA23 & AB23 -> SDNO | AD23: =COUNT(F23:Z23) -> 1 | AE23: =HLOOKUP(AC23, 'Hiring Processes'!$A$3:$G$18, 2, FALSE) -> 4 | AF23: =4+AD23 -> 5 | AG23: =OFFSET('Hiring Processes'!$A$1,(Candidates!AF23),(Candidates!AE23)) -> Send Technical Assessment | AH23: =IF(AP23=TRUE, "FAIL", OFFSET('Hiring Processes'!$A$1,(AF23),(Candidates!AE23))) -> Send Technical Assessment | AI23: =IF(AND(F23<'Passing Scores'!$B$1, COUNT(F23) = 1),TRUE,FALSE) -> FALSE | AJ23: =IF(AND(I23<'Passing Scores'!$B$3, COUNT(I23)=1),TRUE, FALSE) -> FALSE | AK23: =IF(AND(L23<'Passing Scores'!$B$4,COUNT(L23)=1),TRUE, FALSE) -> FALSE | AL23: =IF(AND(O23<'Passing Scores'!$B$5,COUNT(O23)=1),TRUE, FALSE) -> FALSE | AM23: =IF(AND(R23<'Passing Scores'!$B$6,COUNT(R23)=1),TRUE, FALSE) -> FALSE | AN23: =IF(AND(U23<'Passing Scores'!$B$7,COUNT(U23)=1),TRUE, FALSE) -> FALSE | AO23: =IF(AND(X23<'Passing Scores'!$B$8,COUNT(X23)=1),TRUE, FALSE) -> FALSE | AP23: =OR(AI23,AJ23,AK23,AL23,AM23,AN23,AO23) -> FALSE | AQ23: ='Passing Scores'!$B$1 -> 5 | AR23: ='Passing Scores'!$B$2 -> 8 | AS23: ='Passing Scores'!$B$3 -> 7 | AT23: ='Passing Scores'!$B$4 -> 6 | AU23: ='Passing Scores'!$B$5 -> 7 | AV23: ='Passing Scores'!$B$6 -> 6 | AW23: ='Passing Scores'!$B$7 -> 8 | AX23: ='Passing Scores'!$B$8 -> 8
A24: Won Reasley | B24: =AH24 -> Send Personality Assessment | C24: Commercial Lead | D24: =VLOOKUP(C24, 'Job Info'!A:C, 2, FALSE) -> Commercial Team | E24: =IF(F24 >= VLOOKUP("Resume Exceed", 'Passing Scores'!A:B, 2, FALSE), "yes", "no") -> no | F24: 7 | AA24: =VLOOKUP(C24, 'Job Info'!A:C, 3, FALSE) -> CT | AB24: =UPPER(E24) -> NO | AC24: =AA24 & AB24 -> CTNO | AD24: =COUNT(F24:Z24) -> 1 | AE24: =HLOOKUP(AC24, 'Hiring Processes'!$A$3:$G$18, 2, FALSE) -> 2 | AF24: =4+AD24 -> 5 | AG24: =OFFSET('Hiring Processes'!$A$1,(Candidates!AF24),(Candidates!AE24)) -> Send Personality Assessment | AH24: =IF(AP24=TRUE, "FAIL", OFFSET('Hiring Processes'!$A$1,(AF24),(Candidates!AE24))) -> Send Personality Assessment | AI24: =IF(AND(F24<'Passing Scores'!$B$1, COUNT(F24) = 1),TRUE,FALSE) -> FALSE | AJ24: =IF(AND(I24<'Passing Scores'!$B$3, COUNT(I24)=1),TRUE, FALSE) -> FALSE | AK24: =IF(AND(L24<'Passing Scores'!$B$4,COUNT(L24)=1),TRUE, FALSE) -> FALSE | AL24: =IF(AND(O24<'Passing Scores'!$B$5,COUNT(O24)=1),TRUE, FALSE) -> FALSE | AM24: =IF(AND(R24<'Passing Scores'!$B$6,COUNT(R24)=1),TRUE, FALSE) -> FALSE | AN24: =IF(AND(U24<'Passing Scores'!$B$7,COUNT(U24)=1),TRUE, FALSE) -> FALSE | AO24: =IF(AND(X24<'Passing Scores'!$B$8,COUNT(X24)=1),TRUE, FALSE) -> FALSE | AP24: =OR(AI24,AJ24,AK24,AL24,AM24,AN24,AO24) -> FALSE | AQ24: ='Passing Scores'!$B$1 -> 5 | AR24: ='Passing Scores'!$B$2 -> 8 | AS24: ='Passing Scores'!$B$3 -> 7 | AT24: ='Passing Scores'!$B$4 -> 6 | AU24: ='Passing Scores'!$B$5 -> 7 | AV24: ='Passing Scores'!$B$6 -> 6 | AW24: ='Passing Scores'!$B$7 -> 8 | AX24: ='Passing Scores'!$B$8 -> 8
... A30: Merhrdad Pirnia | B30: =AH30 -> Schedule Initial Meeting | C30: Back-End Developer | D30: =VLOOKUP(C30, 'Job Info'!A:C, 2, FALSE) -> Software Developer | E30: =IF(F30 >= VLOOKUP("Resume Exceed", 'Passing Scores'!A:B, 2, FALSE), "yes", "no") -> yes | F30: 9 | AA30: =VLOOKUP(C30, 'Job Info'!A:C, 3, FALSE) -> SD | AB30: =UPPER(E30) -> YES | AC30: =AA30 & AB30 -> SDYES | AD30: =COUNT(F30:Z30) -> 1 | AE30: =HLOOKUP(AC30, 'Hiring Processes'!$A$3:$G$18, 2, FALSE) -> 3 | AF30: =4+AD30 -> 5 | AG30: =OFFSET('Hiring Processes'!$A$1,(Candidates!AF30),(Candidates!AE30)) -> Schedule Initial Meeting | AH30: =IF(AP30=TRUE, "FAIL", OFFSET('Hiring Processes'!$A$1,(AF30),(Candidates!AE30))) -> Schedule Initial Meeting | AI30: =IF(AND(F30<'Passing Scores'!$B$1, COUNT(F30) = 1),TRUE,FALSE) -> FALSE | AJ30: =IF(AND(I30<'Passing Scores'!$B$3, COUNT(I30)=1),TRUE, FALSE) -> FALSE | AK30: =IF(AND(L30<'Passing Scores'!$B$4,COUNT(L30)=1),TRUE, FALSE) -> FALSE | AL30: =IF(AND(O30<'Passing Scores'!$B$5,COUNT(O30)=1),TRUE, FALSE) -> FALSE | AM30: =IF(AND(R30<'Passing Scores'!$B$6,COUNT(R30)=1),TRUE, FALSE) -> FALSE | AN30: =IF(AND(U30<'Passing Scores'!$B$7,COUNT(U30)=1),TRUE, FALSE) -> FALSE | AO30: =IF(AND(X30<'Passing Scores'!$B$8,COUNT(X30)=1),TRUE, FALSE) -> FALSE | AP30: =OR(AI30,AJ30,AK30,AL30,AM30,AN30,AO30) -> FALSE | AQ30: ='Passing Scores'!$B$1 -> 5 | AR30: ='Passing Scores'!$B$2 -> 8 | AS30: ='Passing Scores'!$B$3 -> 7 | AT30: ='Passing Scores'!$B$4 -> 6 | AU30: ='Passing Scores'!$B$5 -> 7 | AV30: ='Passing Scores'!$B$6 -> 6 | AW30: ='Passing Scores'!$B$7 -> 8 | AX30: ='Passing Scores'!$B$8 -> 8

Sheet Passing Scores
A1: Resume Critique | B1: 5 | D1: Minimum score to pass each stage (0 to 10).
A2: Resume Exceed | B2: 8 | D2: Yellow cells are inputs. Change one and the Candidates tab and Dashboard update.
A3: Tech Assessment | B3: 7 | D3: "Resume Exceed" is the score that marks a candidate as exceeding expectations.
A4: Initial Meeting | B4: 6
A5: Portfolio | B5: 7
A6: Personality Assessment | B6: 6
A7: Technical Interview | B7: 8
A8: Final Interview | B8: 8

Sheet Job Info
A1: Position | B1: Category | C1: Process Code
A2: Front-End Developer | B2: Software Developer | C2: SD
A3: Back-End Developer | B3: Software Developer | C3: SD
A4: Infrastructure Developer | B4: Software Developer | C4: SD
A5: UI Designer | B5: Graphic Designer | C5: GD
A6: UX Designer | B6: Graphic Designer | C6: GD
A7: Multimedia Creator | B7: Graphic Designer | C7: GD
A8: Business Operations Associate | B8: Commercial Team | C8: CT
A9: Commercial Lead | B9: Commercial Team | C9: CT

Sheet Hiring Processes
A1: Process | B1: Commercial Team | D1: Software Developer | F1: Graphic Designer
A2: Exceeding | B2: Yes | C2: No | D2: Yes | E2: No | F2: Yes | G2: No
A3: Code | B3: CTYES | C3: CTNO | D3: SDYES | E3: SDNO | F3: GDYES | G3: GDNO
A4: Number | B4: 1 | C4: 2 | D4: 3 | E4: 4 | F4: 5 | G4: 6
A5: Step1 | B5: Review Resume | C5: Review Resume | D5: Review Resume | E5: Review Resume | F5: Review Resume | G5: Review Resume
A6: Step2 | B6: Schedule Initial Meeting | C6: Send Personality Assessment | D6: Schedule Initial Meeting | E6: Send Technical Assessment | F6: Schedule Initial Meeting | G6: Ask for Portfolio
A7: Step3 | B7: Conduct Initial Meeting | C7: Write Personality Assessment | D7: Conduct Initial Meeting | E7: Write Technical Assessment | F7: Conduct Initial Meeting | G7: Send Portfolio
A8: Step4 | B8: Review Initial Meeting | C8: Review Personality Assessment | D8: Review Initial Meeting | E8: Review Technical Assessment | F8: Review Initial Meeting | G8: Review Portfolio
A9: Step5 | B9: Send Personality Assessment | C9: Schedule Initial Meeting | D9: Send Technical Assessment | E9: Schedule Initial Meeting | F9: Ask for Portfolio | G9: Schedule Initial Meeting
A10: Step6 | B10: Write Personality Assessment | C10: Conduct Initial Meeting | D10: Write Technical Assessment | E10: Conduct Initial Meeting | F10: Send Portfolio | G10: Conduct Initial Meeting
A11: Step7 | B11: Review Personality Assessment | C11: Review Initial Meeting | D11: Review Technical Assessment | E11: Review Initial Meeting | F11: Review Portfolio | G11: Review Initial Meeting
A12: Step8 | B12: Schedule Final Interview | C12: Schedule Final Interview | D12: Schedule Technical Interview | E12: Schedule Technical Interview | F12: Send Personality Assessment | G12: Send Personality Assessment
A13: Step9 | B13: Conduct Final Interview | C13: Conduct Final Interview | D13: Conduct Technical Interview | E13: Conduct Technical Interview | F13: Write Personality Assessment | G13: Write Personality Assessment
A14: Step10 | B14: Review Final Interview | C14: Review Final Interview | D14: Review Technical Interview | E14: Review Technical Interview | F14: Review Personality Assessment | G14: Review Personality Assessment
A15: Step11 | B15: Send Offer | C15: Send Offer | D15: Schedule Final Interview | E15: Schedule Final Interview | F15: Schedule Final Interview | G15: Schedule Final Interview
A16: Step12 | B16: Sign Offer | C16: Sign Offer | D16: Conduct Final Interview | E16: Conduct Final Interview | F16: Conduct Final Interview | G16: Conduct Final Interview
A17: Step13 | B17: Hired! | C17: Hired! | D17: Review Final Interview | E17: Review Final Interview | F17: Review Final Interview | G17: Review Final Interview
A18: Step14 | D18: Send Offer | E18: Send Offer | F18: Send Offer | G18: Send Offer
A19: Step15 | D19: Sign Offer | E19: Sign Offer | F19: Sign Offer | G19: Sign Offer
A20: Step16 | D20: Hired! | E20: Hired! | F20: Hired! | G20: Hired!

Sheet Stage_Feed
A1: Candidate | B1: Position | C1: Category | D1: Stage Order | E1: Stage | F1: Score | G1: Min Score | H1: Result | I1: Next Step | K1: Candidate row | L1: Stage # | N1: Stage Order | O1: Stage | P1: Candidates column # | Q1: Min Score
A2: =IF(INDEX(Candidates!$A$1:$A$500,K2)="","",INDEX(Candidates!$A$1:$A$500,K2)) -> William S Preston | B2: =IF(A2="","",INDEX(Candidates!$C$1:$C$500,K2)) -> Front-End Developer | C2: =IF(A2="","",INDEX(Candidates!$D$1:$D$500,K2)) -> Software Developer | D2: =IF(A2="","",L2) -> 1 | E2: =IF(A2="","",INDEX($O$2:$O$8,L2)) -> Resume Review | F2: =IF(A2="","",IF(ISNUMBER(INDEX(Candidates!$A$1:$Z$500,K2,INDEX($P$2:$P$8,L2))),INDEX(Candidates!$A$1:$Z$500,K2,INDEX($P$2:$P$8,L2)),"")) -> 7 | G2: =IF(A2="","",INDEX($Q$2:$Q$8,L2)) -> 5 | H2: =IF(A2="","",IF(F2="","Not yet scored",IF(F2>=G2,"Pass","Fail"))) -> Pass | I2: =IF(A2="","",INDEX(Candidates!$B$1:$B$500,K2)) -> FAIL | K2: =INT((ROW()-2)/7)+2 -> 2 | L2: =MOD(ROW()-2,7)+1 -> 1 | N2: 1 | O2: Resume Review | P2: 6 | Q2: ='Passing Scores'!$B$1 -> 5
A3: =IF(INDEX(Candidates!$A$1:$A$500,K3)="","",INDEX(Candidates!$A$1:$A$500,K3)) -> William S Preston | B3: =IF(A3="","",INDEX(Candidates!$C$1:$C$500,K3)) -> Front-End Developer | C3: =IF(A3="","",INDEX(Candidates!$D$1:$D$500,K3)) -> Software Developer | D3: =IF(A3="","",L3) -> 2 | E3: =IF(A3="","",INDEX($O$2:$O$8,L3)) -> Tech Assessment | F3: =IF(A3="","",IF(ISNUMBER(INDEX(Candidates!$A$1:$Z$500,K3,INDEX($P$2:$P$8,L3))),INDEX(Candidates!$A$1:$Z$500,K3,INDEX($P$2:$P$8,L3)),"")) -> 7 | G3: =IF(A3="","",INDEX($Q$2:$Q$8,L3)) -> 7 | H3: =IF(A3="","",IF(F3="","Not yet scored",IF(F3>=G3,"Pass","Fail"))) -> Pass | I3: =IF(A3="","",INDEX(Candidates!$B$1:$B$500,K3)) -> FAIL | K3: =INT((ROW()-2)/7)+2 -> 2 | L3: =MOD(ROW()-2,7)+1 -> 2 | N3: 2 | O3: Tech Assessment | P3: 9 | Q3: ='Passing Scores'!$B$3 -> 7
A4: =IF(INDEX(Candidates!$A$1:$A$500,K4)="","",INDEX(Candidates!$A$1:$A$500,K4)) -> William S Preston | B4: =IF(A4="","",INDEX(Candidates!$C$1:$C$500,K4)) -> Front-End Developer | C4: =IF(A4="","",INDEX(Candidates!$D$1:$D$500,K4)) -> Software Developer | D4: =IF(A4="","",L4) -> 3 | E4: =IF(A4="","",INDEX($O$2:$O$8,L4)) -> Initial Meeting | F4: =IF(A4="","",IF(ISNUMBER(INDEX(Candidates!$A$1:$Z$500,K4,INDEX($P$2:$P$8,L4))),INDEX(Candidates!$A$1:$Z$500,K4,INDEX($P$2:$P$8,L4)),"")) -> 5 | G4: =IF(A4="","",INDEX($Q$2:$Q$8,L4)) -> 6 | H4: =IF(A4="","",IF(F4="","Not yet scored",IF(F4>=G4,"Pass","Fail"))) -> Fail | I4: =IF(A4="","",INDEX(Candidates!$B$1:$B$500,K4)) -> FAIL | K4: =INT((ROW()-2)/7)+2 -> 2 | L4: =MOD(ROW()-2,7)+1 -> 3 | N4: 3 | O4: Initial Meeting | P4: 12 | Q4: ='Passing Scores'!$B$4 -> 6
A5: =IF(INDEX(Candidates!$A$1:$A$500,K5)="","",INDEX(Candidates!$A$1:$A$500,K5)) -> William S Preston | B5: =IF(A5="","",INDEX(Candidates!$C$1:$C$500,K5)) -> Front-End Developer | C5: =IF(A5="","",INDEX(Candidates!$D$1:$D$500,K5)) -> Software Developer | D5: =IF(A5="","",L5) -> 4 | E5: =IF(A5="","",INDEX($O$2:$O$8,L5)) -> Portfolio | F5: =IF(A5="","",IF(ISNUMBER(INDEX(Candidates!$A$1:$Z$500,K5,INDEX($P$2:$P$8,L5))),INDEX(Candidates!$A$1:$Z$500,K5,INDEX($P$2:$P$8,L5)),"")) -> 1 | G5: =IF(A5="","",INDEX($Q$2:$Q$8,L5)) -> 7 | H5: =IF(A5="","",IF(F5="","Not yet scored",IF(F5>=G5,"Pass","Fail"))) -> Fail | I5: =IF(A5="","",INDEX(Candidates!$B$1:$B$500,K5)) -> FAIL | K5: =INT((ROW()-2)/7)+2 -> 2 | L5: =MOD(ROW()-2,7)+1 -> 4 | N5: 4 | O5: Portfolio | P5: 15 | Q5: ='Passing Scores'!$B$5 -> 7
A6: =IF(INDEX(Candidates!$A$1:$A$500,K6)="","",INDEX(Candidates!$A$1:$A$500,K6)) -> William S Preston | B6: =IF(A6="","",INDEX(Candidates!$C$1:$C$500,K6)) -> Front-End Developer | C6: =IF(A6="","",INDEX(Candidates!$D$1:$D$500,K6)) -> Software Developer | D6: =IF(A6="","",L6) -> 5 | E6: =IF(A6="","",INDEX($O$2:$O$8,L6)) -> Personality Assessment | F6: =IF(A6="","",IF(ISNUMBER(INDEX(Candidates!$A$1:$Z$500,K6,INDEX($P$2:$P$8,L6))),INDEX(Candidates!$A$1:$Z$500,K6,INDEX($P$2:$P$8,L6)),"")) -> 1 | G6: =IF(A6="","",INDEX($Q$2:$Q$8,L6)) -> 6 | H6: =IF(A6="","",IF(F6="","Not yet scored",IF(F6>=G6,"Pass","Fail"))) -> Fail | I6: =IF(A6="","",INDEX(Candidates!$B$1:$B$500,K6)) -> FAIL | K6: =INT((ROW()-2)/7)+2 -> 2 | L6: =MOD(ROW()-2,7)+1 -> 5 | N6: 5 | O6: Personality Assessment | P6: 18 | Q6: ='Passing Scores'!$B$6 -> 6
A7: =IF(INDEX(Candidates!$A$1:$A$500,K7)="","",INDEX(Candidates!$A$1:$A$500,K7)) -> William S Preston | B7: =IF(A7="","",INDEX(Candidates!$C$1:$C$500,K7)) -> Front-End Developer | C7: =IF(A7="","",INDEX(Candidates!$D$1:$D$500,K7)) -> Software Developer | D7: =IF(A7="","",L7) -> 6 | E7: =IF(A7="","",INDEX($O$2:$O$8,L7)) -> Technical Interview | F7: =IF(A7="","",IF(ISNUMBER(INDEX(Candidates!$A$1:$Z$500,K7,INDEX($P$2:$P$8,L7))),INDEX(Candidates!$A$1:$Z$500,K7,INDEX($P$2:$P$8,L7)),"")) -> 1 | G7: =IF(A7="","",INDEX($Q$2:$Q$8,L7)) -> 8 | H7: =IF(A7="","",IF(F7="","Not yet scored",IF(F7>=G7,"Pass","Fail"))) -> Fail | I7: =IF(A7="","",INDEX(Candidates!$B$1:$B$500,K7)) -> FAIL | K7: =INT((ROW()-2)/7)+2 -> 2 | L7: =MOD(ROW()-2,7)+1 -> 6 | N7: 6 | O7: Technical Interview | P7: 21 | Q7: ='Passing Scores'!$B$7 -> 8
A8: =IF(INDEX(Candidates!$A$1:$A$500,K8)="","",INDEX(Candidates!$A$1:$A$500,K8)) -> William S Preston | B8: =IF(A8="","",INDEX(Candidates!$C$1:$C$500,K8)) -> Front-End Developer | C8: =IF(A8="","",INDEX(Candidates!$D$1:$D$500,K8)) -> Software Developer | D8: =IF(A8="","",L8) -> 7 | E8: =IF(A8="","",INDEX($O$2:$O$8,L8)) -> Final Interview | F8: =IF(A8="","",IF(ISNUMBER(INDEX(Candidates!$A$1:$Z$500,K8,INDEX($P$2:$P$8,L8))),INDEX(Candidates!$A$1:$Z$500,K8,INDEX($P$2:$P$8,L8)),"")) -> 1 | G8: =IF(A8="","",INDEX($Q$2:$Q$8,L8)) -> 8 | H8: =IF(A8="","",IF(F8="","Not yet scored",IF(F8>=G8,"Pass","Fail"))) -> Fail | I8: =IF(A8="","",INDEX(Candidates!$B$1:$B$500,K8)) -> FAIL | K8: =INT((ROW()-2)/7)+2 -> 2 | L8: =MOD(ROW()-2,7)+1 -> 7 | N8: 7 | O8: Final Interview | P8: 24 | Q8: ='Passing Scores'!$B$8 -> 8
A9: =IF(INDEX(Candidates!$A$1:$A$500,K9)="","",INDEX(Candidates!$A$1:$A$500,K9)) -> Ted Logan | B9: =IF(A9="","",INDEX(Candidates!$C$1:$C$500,K9)) -> Back-End Developer | C9: =IF(A9="","",INDEX(Candidates!$D$1:$D$500,K9)) -> Software Developer | D9: =IF(A9="","",L9) -> 1 | E9: =IF(A9="","",INDEX($O$2:$O$8,L9)) -> Resume Review | F9: =IF(A9="","",IF(ISNUMBER(INDEX(Candidates!$A$1:$Z$500,K9,INDEX($P$2:$P$8,L9))),INDEX(Candidates!$A$1:$Z$500,K9,INDEX($P$2:$P$8,L9)),"")) -> 9 | G9: =IF(A9="","",INDEX($Q$2:$Q$8,L9)) -> 5 | H9: =IF(A9="","",IF(F9="","Not yet scored",IF(F9>=G9,"Pass","Fail"))) -> Pass | I9: =IF(A9="","",INDEX(Candidates!$B$1:$B$500,K9)) -> Write Technical Assessment | K9: =INT((ROW()-2)/7)+2 -> 3 | L9: =MOD(ROW()-2,7)+1 -> 1
A10: =IF(INDEX(Candidates!$A$1:$A$500,K10)="","",INDEX(Candidates!$A$1:$A$500,K10)) -> Ted Logan | B10: =IF(A10="","",INDEX(Candidates!$C$1:$C$500,K10)) -> Back-End Developer | C10: =IF(A10="","",INDEX(Candidates!$D$1:$D$500,K10)) -> Software Developer | D10: =IF(A10="","",L10) -> 2 | E10: =IF(A10="","",INDEX($O$2:$O$8,L10)) -> Tech Assessment | F10: =IF(A10="","",IF(ISNUMBER(INDEX(Candidates!$A$1:$Z$500,K10,INDEX($P$2:$P$8,L10))),INDEX(Candidates!$A$1:$Z$500,K10,INDEX($P$2:$P$8,L10)),"")) | G10: =IF(A10="","",INDEX($Q$2:$Q$8,L10)) -> 7 | H10: =IF(A10="","",IF(F10="","Not yet scored",IF(F10>=G10,"Pass","Fail"))) -> Not yet scored | I10: =IF(A10="","",INDEX(Candidates!$B$1:$B$500,K10)) -> Write Technical Assessment | K10: =INT((ROW()-2)/7)+2 -> 3 | L10: =MOD(ROW()-2,7)+1 -> 2 | N10: Column # is the position of each stage score on the Candidates tab (F=6, I=9, L=12, O=15, R=18, U=21, X=24).
A11: =IF(INDEX(Candidates!$A$1:$A$500,K11)="","",INDEX(Candidates!$A$1:$A$500,K11)) -> Ted Logan | B11: =IF(A11="","",INDEX(Candidates!$C$1:$C$500,K11)) -> Back-End Developer | C11: =IF(A11="","",INDEX(Candidates!$D$1:$D$500,K11)) -> Software Developer | D11: =IF(A11="","",L11) -> 3 | E11: =IF(A11="","",INDEX($O$2:$O$8,L11)) -> Initial Meeting | F11: =IF(A11="","",IF(ISNUMBER(INDEX(Candidates!$A$1:$Z$500,K11,INDEX($P$2:$P$8,L11))),INDEX(Candidates!$A$1:$Z$500,K11,INDEX($P$2:$P$8,L11)),"")) -> 6 | G11: =IF(A11="","",INDEX($Q$2:$Q$8,L11)) -> 6 | H11: =IF(A11="","",IF(F11="","Not yet scored",IF(F11>=G11,"Pass","Fail"))) -> Pass | I11: =IF(A11="","",INDEX(Candidates!$B$1:$B$500,K11)) -> Write Technical Assessment | K11: =INT((ROW()-2)/7)+2 -> 3 | L11: =MOD(ROW()-2,7)+1 -> 3 | N11: This tab feeds Power BI. It covers the first 100 candidates on the Candidates tab, 7 stages each.
A12: =IF(INDEX(Candidates!$A$1:$A$500,K12)="","",INDEX(Candidates!$A$1:$A$500,K12)) -> Ted Logan | B12: =IF(A12="","",INDEX(Candidates!$C$1:$C$500,K12)) -> Back-End Developer | C12: =IF(A12="","",INDEX(Candidates!$D$1:$D$500,K12)) -> Software Developer | D12: =IF(A12="","",L12) -> 4 | E12: =IF(A12="","",INDEX($O$2:$O$8,L12)) -> Portfolio | F12: =IF(A12="","",IF(ISNUMBER(INDEX(Candidates!$A$1:$Z$500,K12,INDEX($P$2:$P$8,L12))),INDEX(Candidates!$A$1:$Z$500,K12,INDEX($P$2:$P$8,L12)),"")) | G12: =IF(A12="","",INDEX($Q$2:$Q$8,L12)) -> 7 | H12: =IF(A12="","",IF(F12="","Not yet scored",IF(F12>=G12,"Pass","Fail"))) -> Not yet scored | I12: =IF(A12="","",INDEX(Candidates!$B$1:$B$500,K12)) -> Write Technical Assessment | K12: =INT((ROW()-2)/7)+2 -> 3 | L12: =MOD(ROW()-2,7)+1 -> 4 | N12: Empty rows (no candidate yet) come back blank. Filter them out in Power Query.
A13: =IF(INDEX(Candidates!$A$1:$A$500,K13)="","",INDEX(Candidates!$A$1:$A$500,K13)) -> Ted Logan | B13: =IF(A13="","",INDEX(Candidates!$C$1:$C$500,K13)) -> Back-End Developer | C13: =IF(A13="","",INDEX(Candidates!$D$1:$D$500,K13)) -> Software Developer | D13: =IF(A13="","",L13) -> 5 | E13: =IF(A13="","",INDEX($O$2:$O$8,L13)) -> Personality Assessment | F13: =IF(A13="","",IF(ISNUMBER(INDEX(Candidates!$A$1:$Z$500,K13,INDEX($P$2:$P$8,L13))),INDEX(Candidates!$A$1:$Z$500,K13,INDEX($P$2:$P$8,L13)),"")) | G13: =IF(A13="","",INDEX($Q$2:$Q$8,L13)) -> 6 | H13: =IF(A13="","",IF(F13="","Not yet scored",IF(F13>=G13,"Pass","Fail"))) -> Not yet scored | I13: =IF(A13="","",INDEX(Candidates!$B$1:$B$500,K13)) -> Write Technical Assessment | K13: =INT((ROW()-2)/7)+2 -> 3 | L13: =MOD(ROW()-2,7)+1 -> 5
A14: =IF(INDEX(Candidates!$A$1:$A$500,K14)="","",INDEX(Candidates!$A$1:$A$500,K14)) -> Ted Logan | B14: =IF(A14="","",INDEX(Candidates!$C$1:$C$500,K14)) -> Back-End Developer | C14: =IF(A14="","",INDEX(Candidates!$D$1:$D$500,K14)) -> Software Developer | D14: =IF(A14="","",L14) -> 6 | E14: =IF(A14="","",INDEX($O$2:$O$8,L14)) -> Technical Interview | F14: =IF(A14="","",IF(ISNUMBER(INDEX(Candidates!$A$1:$Z$500,K14,INDEX($P$2:$P$8,L14))),INDEX(Candidates!$A$1:$Z$500,K14,INDEX($P$2:$P$8,L14)),"")) | G14: =IF(A14="","",INDEX($Q$2:$Q$8,L14)) -> 8 | H14: =IF(A14="","",IF(F14="","Not yet scored",IF(F14>=G14,"Pass","Fail"))) -> Not yet scored | I14: =IF(A14="","",INDEX(Candidates!$B$1:$B$500,K14)) -> Write Technical Assessment | K14: =INT((ROW()-2)/7)+2 -> 3 | L14: =MOD(ROW()-2,7)+1 -> 6
A15: =IF(INDEX(Candidates!$A$1:$A$500,K15)="","",INDEX(Candidates!$A$1:$A$500,K15)) -> Ted Logan | B15: =IF(A15="","",INDEX(Candidates!$C$1:$C$500,K15)) -> Back-End Developer | C15: =IF(A15="","",INDEX(Candidates!$D$1:$D$500,K15)) -> Software Developer | D15: =IF(A15="","",L15) -> 7 | E15: =IF(A15="","",INDEX($O$2:$O$8,L15)) -> Final Interview | F15: =IF(A15="","",IF(ISNUMBER(INDEX(Candidates!$A$1:$Z$500,K15,INDEX($P$2:$P$8,L15))),INDEX(Candidates!$A$1:$Z$500,K15,INDEX($P$2:$P$8,L15)),"")) -> 22 | G15: =IF(A15="","",INDEX($Q$2:$Q$8,L15)) -> 8 | H15: =IF(A15="","",IF(F15="","Not yet scored",IF(F15>=G15,"Pass","Fail"))) -> Pass | I15: =IF(A15="","",INDEX(Candidates!$B$1:$B$500,K15)) -> Write Technical Assessment | K15: =INT((ROW()-2)/7)+2 -> 3 | L15: =MOD(ROW()-2,7)+1 -> 7
